<?xml version="1.0"?>
<robot name="door">

  <material name="brown" >
    <color rgba="0.4 0.25 0.07 1" />
  </material>

  <material name="black">
    <color rgba="0 0 0 1"/>
  </material>

  <link name="for_open">
    <visual>
      <origin xyz="0 0 1"/>
      <geometry>
        <box size="0.05 0.1 2"/>
      </geometry>
      <material name="black"/>
    </visual>

    <collision>
      <origin xyz="0 0 1"/>
      <geometry>
        <box size="0.05 0.1 2"/>
      </geometry>
    </collision>

    <inertial>
      <mass value="5"/>
      <inertia ixx="0.1" ixy="0" ixz="0"
               iyy="0.1" iyz="0"
               izz="0.1"/>
    </inertial>
  </link>

  <link name="door">
    <visual>
      <origin xyz="0.5 0 1"/>
      <geometry>
        <box size="1 0.05 2"/>
      </geometry>
      <material name="brown"/>
    </visual>

    <collision>
      <origin xyz="0.5 0 1"/>
      <geometry>
        <box size="1 0.05 2"/>
      </geometry>
    </collision>

    <inertial>
      <mass value="0.5"/>
      <inertia ixx="0.2" ixy="0" ixz="0"
               iyy="0.2" iyz="0"
               izz="0.2"/>
    </inertial>
  </link>

  <joint name="open" type="revolute">
    <parent link="for_open"/>
    <child link="door"/>
    <origin xyz="0 0 0" rpy="0 0 0"/>
    <axis xyz="0 0 1"/>
    <limit lower="0" upper="1.57" effort="10" velocity="1"/>
  </joint>
</robot>
